{"uuid": "2ebf830f-11f9-46ce-a388-d7e982f3f36f", "children": ["a6d89adb-6dcc-46b4-a0f8-97f874a76907", "b25a3442-9174-4857-9a7f-3b0c81dc77d9", "44f1cc4f-3d29-4117-bc0a-3e5ebae19abe"], "befores": [{"name": "_xunit_setup_class_fixture_TestTuHu", "status": "passed", "start": 1715957161339, "stop": 1715957170207}], "afters": [{"name": "_xunit_setup_class_fixture_TestTuHu::0", "status": "broken", "statusDetails": {"message": "selenium.common.exceptions.WebDriverException: Message: An unknown server-side error occurred while processing the command. Original error: Could not proxy. Proxy error: Could not proxy command to remote server. Original error: Error: socket hang up\nStacktrace:\nUnknownError: An unknown server-side error occurred while processing the command. Original error: Could not proxy. Proxy error: Could not proxy command to remote server. Original error: Error: socket hang up\n    at getResponseForW3CError (C:\\Program Files\\Appium\\resources\\app\\node_modules\\appium\\node_modules\\appium-base-driver\\lib\\protocol\\errors.js:804:9)\n    at asyncHandler (C:\\Program Files\\Appium\\resources\\app\\node_modules\\appium\\node_modules\\appium-base-driver\\lib\\protocol\\protocol.js:392:37)\n", "trace": "  File \"D:\\python3.10.4\\lib\\site-packages\\allure_commons\\_allure.py\", line 221, in __call__\n    return self._fixture_function(*args, **kwargs)\n  File \"D:\\python3.10.4\\lib\\site-packages\\_pytest\\fixtures.py\", line 893, in _teardown_yield_fixture\n    next(it)\n  File \"D:\\python3.10.4\\lib\\site-packages\\_pytest\\python.py\", line 785, in xunit_setup_class_fixture\n    _call_with_optional_argument(func, cls)\n  File \"D:\\python3.10.4\\lib\\site-packages\\_pytest\\python.py\", line 709, in _call_with_optional_argument\n    func(arg)\n  File \"D:\\wangtao_app_test\\script\\test_tuhu.py\", line 11, in teardown_class\n    self.operation.close_driver()\n  File \"D:\\wangtao_app_test\\common\\operation.py\", line 21, in close_driver\n    self.driver.quit()\n  File \"D:\\python3.10.4\\lib\\site-packages\\selenium\\webdriver\\remote\\webdriver.py\", line 458, in close\n    self.execute(Command.CLOSE)\n  File \"D:\\python3.10.4\\lib\\site-packages\\selenium\\webdriver\\remote\\webdriver.py\", line 347, in execute\n    self.error_handler.check_response(response)\n  File \"D:\\python3.10.4\\lib\\site-packages\\appium\\webdriver\\errorhandler.py\", line 122, in check_response\n    raise exception_class(msg=message, stacktrace=format_stacktrace(stacktrace))\n"}, "start": 1715957173545, "stop": 1715957303575}], "start": 1715957161339, "stop": 1715957303575}